<?xml version="1.0" encoding="UTF-8"?>
<!-- Generated by org.testng.reporters.JUnitReportReporter -->
<testsuite hostname="DESKTOP-KHVMP4M" name="Adv1CucumberFramework.Runners.Runner1" tests="1" failures="0" timestamp="4 May 2019 22:56:56 GMT" time="9.505" errors="1">
  <testcase name="feature" time="9.505" classname="Adv1CucumberFramework.Runners.Runner1">
    <error type="cucumber.runtime.CucumberException" message="java.lang.AssertionError: expected [thankyouforyourmessage!] but found [thankyouforyourmessage!1]">
      <![CDATA[cucumber.runtime.CucumberException: java.lang.AssertionError: expected [thankyouforyourmessage!] but found [thankyouforyourmessage!1]
	at cucumber.api.testng.TestNGCucumberRunner.runCucumber(TestNGCucumberRunner.java:69)
	at cucumber.api.testng.AbstractTestNGCucumberTests.feature(AbstractTestNGCucumberTests.java:21)
	at sun.reflect.NativeMethodAccessorImpl.invoke0(Native Method)
	at sun.reflect.NativeMethodAccessorImpl.invoke(Unknown Source)
	at sun.reflect.DelegatingMethodAccessorImpl.invoke(Unknown Source)
	at java.lang.reflect.Method.invoke(Unknown Source)
	at org.testng.internal.MethodInvocationHelper.invokeMethod(MethodInvocationHelper.java:86)
	at org.testng.internal.Invoker.invokeMethod(Invoker.java:643)
	at org.testng.internal.Invoker.invokeTestMethod(Invoker.java:820)
	at org.testng.internal.Invoker.invokeTestMethods(Invoker.java:1128)
	at org.testng.internal.TestMethodWorker.invokeTestMethods(TestMethodWorker.java:129)
	at org.testng.internal.TestMethodWorker.run(TestMethodWorker.java:112)
	at org.testng.TestRunner.privateRun(TestRunner.java:782)
	at org.testng.TestRunner.run(TestRunner.java:632)
	at org.testng.SuiteRunner.runTest(SuiteRunner.java:366)
	at org.testng.SuiteRunner.runSequentially(SuiteRunner.java:361)
	at org.testng.SuiteRunner.privateRun(SuiteRunner.java:319)
	at org.testng.SuiteRunner.run(SuiteRunner.java:268)
	at org.testng.SuiteRunnerWorker.runSuite(SuiteRunnerWorker.java:52)
	at org.testng.SuiteRunnerWorker.run(SuiteRunnerWorker.java:86)
	at org.testng.TestNG.runSuitesSequentially(TestNG.java:1244)
	at org.testng.TestNG.runSuitesLocally(TestNG.java:1169)
	at org.testng.TestNG.run(TestNG.java:1064)
	at org.testng.remote.AbstractRemoteTestNG.run(AbstractRemoteTestNG.java:115)
	at org.testng.remote.RemoteTestNG.initAndRun(RemoteTestNG.java:251)
	at org.testng.remote.RemoteTestNG.main(RemoteTestNG.java:77)
Caused by: java.lang.AssertionError: expected [thankyouforyourmessage!] but found [thankyouforyourmessage!1]
	at org.testng.Assert.fail(Assert.java:94)
	at org.testng.Assert.failNotEquals(Assert.java:513)
	at org.testng.Assert.assertEqualsImpl(Assert.java:135)
	at org.testng.Assert.assertEquals(Assert.java:116)
	at org.testng.Assert.assertEquals(Assert.java:190)
	at org.testng.Assert.assertEquals(Assert.java:200)
	at Resources.pageObjects.ContactUs_Page.confirmContactUsFormSubmissionWasSuccessful(ContactUs_Page.java:60)
	at Adv1CucumberFramework.StepDefinitions.ContactUsSteps.the_information_should_successfully_be_submitted_via_the_contact_us_form(ContactUsSteps.java:49)
	at âœ½.Then the information should successfully be submitted via the contact us form(src/test/java/Adv1CucumberFramework/FeatureFiles/ContactUs.feature:12)
]]>
    </error>
  </testcase> <!-- feature -->
</testsuite> <!-- Adv1CucumberFramework.Runners.Runner1 -->
